Workbook

Sheet RESUMEN
A1: 🌿 GrowMore — Panel de Control
A2: Actualizado manualmente. Fecha hoy: =TEXT(TODAY(),"DD/MM/YYYY")
A4: ESTADO ACTUAL — SALAS DE CULTIVO
A5: Sala/Carpa | B5: Variedad(es) | C5: Total Plantas | D5: Etapa Actual | E5: Días en Etapa | G5: Fecha Corte Est. | H5: pH | I5: EC | J5: Temp (°C) | K5: Hum (%) | L5: Notas Rápidas
A6: Sala 1
A7: Sala 2
A8: Sala 3
A9: Sala 4
A10: Sala 5
A11: Sala 6
A12: Carpa 1
A13: Carpa 2
A14: Carpa 3
A15: Carpa 4
A17: 💛 Celdas amarillas = ingreso manual | Etapa Actual: escribe la etapa del ciclo en curso | Fecha Corte Est.: copiar de la hoja de sala
A19: HISTORIAL pH / EC / TEMP / HUM — Sala 1
A20: Fecha | B20: pH | C20: EC (ppm) | D20: Temp (°C) | E20: Hum (%) | F20: PPFD (µmol/m²/s) | G20: Notas

Sheet RAGNAR
A1: 🌱 RAGNAR — Sala de Vegetación
A3: ESQUEJES | F3: MACETAS EN VEGETACIÓN
A4: Variedad | C4: Cantidad | D4: Sala Destino | F4: Variedad | G4: Fecha Ingreso | H4: Cantidad | I4: Sala Destino
A5: Frozen Biscotti #2 | C5: 36 | F5: MR | H5: 36
A6: Blue Zushi | C6: 7 | F6: Guava | H6: 36
A7: HTT #4 | C7: 41
A8: Papaya #5 | C8: 24
A9: Guava | C9: 18
A10: Pink Lemon #2 | C10: 12
A12: PLANTAS MADRES | F12: HISTORIAL pH / EC / TEMP / HUM
A13: Variedad | B13: Última toma de clones | C13: Cantidad | D13: Observaciones | F13: Fecha | G13: pH | H13: EC (ppm) | I13: PPFD (µmol/m²/s) | J13: Notas
A14: Guava | C14: 1
A15: MR | C15: 2
A16: CC | C16: 2
A17: Pink Lemon | C17: 1
A18: HTT #4 | C18: 2
A19: Papaya 5 | C19: 3

Sheet PROYECCIÓN
A1: 🗓️ PROYECCIÓN DE DISPONIBILIDAD POR SALA/CARPA
A2: ℹ️ Generado automáticamente: muestra cuándo y qué variedades estarán Disponibles (post-secado/procesado) en cada Sala o Carpa, según las fechas y variedades cargadas. Vuelve a generar esta hoja cuando actualices los ciclos. Ragnar no se incluye porque no produce cosechas.
A4: Sala / Carpa | B4: Fecha Disponible | C4: Mes | D4: Variedades Disponibles (cantidad)
A5: SALA 6 | B5: 46197 | C5: Junio 2026 | D5: Papaya Feno Hunting (22), Cherry Zoda (19), Brrberry (3), Sour nana (1), Spritz (3)
A6: CARPA 3 | B6: 46214 | C6: Julio 2026 | D6: Guava (37)
A7: SALA 2 | B7: 46221 | C7: Julio 2026 | D7: Guava (30), Mix (10)
A8: SALA 3 | B8: 46234 | C8: Julio 2026 | D8: Lemon Cherry (18), Frozen Biscotti #2 (26), HTT #4 (19), Blue Zushi (9)
A9: SALA 4 | B9: 46240 | C9: Agosto 2026 | D9: Brrberry (16), Cherry Zoda (12), Spritz (22)
A10: SALA 5 | B10: 46252 | C10: Agosto 2026 | D10: Papaya Feno Hunting (33)
A11: CARPA 2 | B11: 46253 | C11: Agosto 2026 | D11: HTT Feno Hunt Mix (25)
A12: SALA 1 | B12: 46262 | C12: Agosto 2026 | D12: Coco (28), MR (44)
A13: CARPA 1 | B13: 46272 | C13: Septiembre 2026 | D13: Cherry Zoda (3), Hot tub time (2), Papaya Feno Hunting (5)
A14: CARPA 4 | B14: 46276 | C14: Septiembre 2026 | D14: Coco (14)

Sheet SALA 1
A1: 🌿 SALA 1 | H1: HISTORIAL pH / EC / TEMP / HUM
H2: Fecha | I2: pH | J2: EC (ppm) | K2: Temp °C | L2: Hum % | M2: PPFD (µmol/m²/s) | N2: Notas
A3: CICLO 1 | H3: 46183 | I3: 5.9 | J3: 1700
A4: Esquejes | B4: 21 | C4: 46122 | H4: 46184 | I4: 6 | J4: 1850
A5: Trasplante a Vaso | B5: 14 | C5: =IF(C4="","",C4+B4) -> 46143
A6: Trasplante Maceta | B6: 14 | C6: =IF(C5="","",C5+B5) -> 46157
A7: Ingreso a Sala | B7: 16 | C7: =IF(C6="","",C6+B6) -> 46171
A8: Floración | B8: 63 | C8: =IF(C7="","",C7+B7) -> 46187
A9: Corte | B9: 2 | C9: =IF(C8="","",C8+B8) -> 46250
A10: Secado | B10: 7 | C10: =IF(C9="","",C9+B9) -> 46252
A11: Procesado | B11: 3 | C11: =IF(C10="","",C10+B10) -> 46259
A12: Disponible | C12: =IF(C11="","",C11+B11) -> 46262
A15: VARIEDADES | B15: Cant.
A16: Coco | B16: 28
A17: MR | B17: 44
A18: TOTAL | B18: =SUM(B16:B17) -> 72
A20: Observaciones:
A21: La programacion de sala 1 se retraso debido a los problemas del timer de ragnar, se evaluo dejar menos unidades y solo de MR, pero las coco recuperaron y se logro 72 unidades. se bajaron todos los mesones y se sello para la implementacion de CO2. Esto genero un desfase aprox de 15 dias. Actualmente estan muy sanas y creciendo a buen ritmo.
A24: CICLO 2
A25: Etapa | B25: Días | C25: Fecha Inicio
A26: Esquejes | B26: 21
A27: Trasplante a Vaso | B27: 14
A28: Trasplante Maceta | B28: 14
A29: Ingreso a Sala | B29: 16 | C29: =C11+1 -> 46260
A30: Floración | B30: 63 | C30: =IF(C29="","",C29+B29) -> 46276
A31: Corte | B31: 2 | C31: =IF(C30="","",C30+B30) -> 46339
A32: Secado | B32: 7 | C32: =IF(C31="","",C31+B31) -> 46341
A33: Procesado | B33: 3 | C33: =IF(C32="","",C32+B32) -> 46348
A34: Disponible | C34: =IF(C33="","",C33+B33) -> 46351
A36: VARIEDADES | B36: Cant.
A39: TOTAL | B39: =SUM(B37:B38) -> 0
A41: Observaciones:
A45: CICLO 3
A46: Etapa | B46: Días | C46: Fecha Inicio
A47: Esquejes | B47: 21
A48: Trasplante a Vaso | B48: 14
A49: Trasplante Maceta | B49: 14
A50: Ingreso a Sala | B50: 16 | C50: =C33+1 -> 46349
A51: Floración | B51: 63 | C51: =IF(C50="","",C50+B50) -> 46365
A52: Corte | B52: 1 | C52: =IF(C51="","",C51+B51) -> 46428
...

Sheet SALA 2
A1: 🌿 SALA 2 | H1: HISTORIAL pH / EC / TEMP / HUM
H2: Fecha | I2: pH | J2: EC (ppm) | K2: Temp °C | L2: Hum % | M2: PPFD (µmol/m²/s) | N2: Notas
A3: CICLO 1 | H3: 46184 | I3: 6.2 | J3: 2300
A4: Etapa | B4: Días | C4: Fecha Inicio
A5: Esquejes | B5: 21 | C5: 46081
A6: Trasplante a Vaso | B6: 14 | C6: =IF(C5="","",C5+B5) -> 46102
A7: Trasplante Maceta | B7: 14 | C7: =IF(C6="","",C6+B6) -> 46116
A8: Ingreso a Sala | B8: 16 | C8: =IF(C7="","",C7+B7) -> 46130
A9: Floración | B9: 63 | C9: =IF(C8="","",C8+B8) -> 46146
A10: Corte | B10: 2 | C10: =IF(C9="","",C9+B9) -> 46209
A11: Secado | B11: 7 | C11: =IF(C10="","",C10+B10) -> 46211
A12: Procesado | B12: 3 | C12: =IF(C11="","",C11+B11) -> 46218
A13: Disponible | C13: =IF(C12="","",C12+B12) -> 46221
A15: VARIEDADES | B15: Cant.
A16: Guava | B16: 30
A17: Mix | B17: 10
A18: TOTAL | B18: =SUM(B16:B17) -> 40
A20: Observaciones:
A24: CICLO 2
A25: Etapa | B25: Días | C25: Fecha Inicio
A26: Esquejes | B26: 21
A27: Trasplante a Vaso | B27: 14
A28: Trasplante Maceta | B28: 14
A29: Ingreso a Sala | B29: 16 | C29: =C12+1 -> 46219
A30: Floración | B30: 63 | C30: =IF(C29="","",C29+B29) -> 46235
A31: Corte | B31: 1 | C31: =IF(C30="","",C30+B30) -> 46298
A32: Secado | B32: 7 | C32: =IF(C31="","",C31+B31) -> 46299
A33: Procesado | B33: 3 | C33: =IF(C32="","",C32+B32) -> 46306
A34: Disponible | C34: =IF(C33="","",C33+B33) -> 46309
A36: VARIEDADES | B36: Cant.
A39: TOTAL | B39: =SUM(B37:B38) -> 0
A41: Observaciones:
A45: CICLO 3
A46: Etapa | B46: Días | C46: Fecha Inicio
A47: Esquejes | B47: 21
A48: Trasplante a Vaso | B48: 14
A49: Trasplante Maceta | B49: 14
A50: Ingreso a Sala | B50: 16 | C50: =C33+1 -> 46307
A51: Floración | B51: 63 | C51: =IF(C50="","",C50+B50) -> 46323
A52: Corte | B52: 1 | C52: =IF(C51="","",C51+B51) -> 46386
...

Sheet SALA 3
A1: 🌿 SALA 3 | H1: HISTORIAL pH / EC / TEMP / HUM
H2: Fecha | I2: pH | J2: EC (ppm) | K2: Temp °C | L2: Hum % | M2: PPFD (µmol/m²/s) | N2: Notas
A3: CICLO 1 | H3: 46184 | I3: 6.1 | J3: 1950
A4: Etapa | B4: Días | C4: Fecha Inicio
A5: Esquejes | B5: 21 | C5: 46095
A6: Trasplante a Vaso | B6: 14 | C6: =IF(C5="","",C5+B5) -> 46116
A7: Trasplante Maceta | B7: 14 | C7: =IF(C6="","",C6+B6) -> 46130
A8: Ingreso a Sala | B8: 16 | C8: =IF(C7="","",C7+B7) -> 46144
A9: Floración | B9: 63 | C9: =IF(C8="","",C8+B8) -> 46160
A10: Corte | B10: 1 | C10: =IF(C9="","",C9+B9) -> 46223
A11: Secado | B11: 7 | C11: =IF(C10="","",C10+B10) -> 46224
A12: Procesado | B12: 3 | C12: =IF(C11="","",C11+B11) -> 46231
A13: Disponible | C13: =IF(C12="","",C12+B12) -> 46234
A15: VARIEDADES | B15: Cant.
A16: Lemon Cherry | B16: 18
A17: Frozen Biscotti #2 | B17: 26
A18: HTT #4 | B18: 19
A19: Blue Zushi | B19: 9
A20: TOTAL | B20: =SUM(B16:B19) -> 72
A22: Observaciones:
A26: CICLO 2
A27: Etapa | B27: Días | C27: Fecha Inicio
A28: Esquejes | B28: 21
A29: Trasplante a Vaso | B29: 14
A30: Trasplante Maceta | B30: 14
A31: Ingreso a Sala | B31: 16 | C31: =C12+1 -> 46232
A32: Floración | B32: 63 | C32: =IF(C31="","",C31+B31) -> 46248
A33: Corte | B33: 3 | C33: =IF(C32="","",C32+B32) -> 46311
A34: Secado | B34: 7 | C34: =IF(C33="","",C33+B33) -> 46314
A35: Procesado | B35: 3 | C35: =IF(C34="","",C34+B34) -> 46321
A36: Disponible | C36: =IF(C35="","",C35+B35) -> 46324
A38: VARIEDADES | B38: Cant.
A41: TOTAL | B41: =SUM(B39:B40) -> 0
A43: Observaciones:
A47: CICLO 3
A48: Etapa | B48: Días | C48: Fecha Inicio
A49: Esquejes | B49: 21
A50: Trasplante a Vaso | B50: 14
A51: Trasplante Maceta | B51: 14
A52: Ingreso a Sala | B52: 16 | C52: =C35+1 -> 46322
...

Sheet SALA 4
A1: 🌿 SALA 4 | H1: HISTORIAL pH / EC / TEMP / HUM
H2: Fecha | I2: pH | J2: EC (ppm) | K2: Temp °C | L2: Hum % | M2: PPFD (µmol/m²/s) | N2: Notas
A3: CICLO 1 | H3: 46184 | I3: 6 | J3: 2100
A4: Etapa | B4: Días | C4: Fecha Inicio
A5: Esquejes | B5: 21 | C5: 46101
A6: Trasplante a Vaso | B6: 14 | C6: =IF(C5="","",C5+B5) -> 46122
A7: Trasplante Maceta | B7: 14 | C7: =IF(C6="","",C6+B6) -> 46136
A8: Ingreso a Sala | B8: 16 | C8: =IF(C7="","",C7+B7) -> 46150
A9: Floración | B9: 63 | C9: =IF(C8="","",C8+B8) -> 46166
A10: Corte | B10: 1 | C10: =IF(C9="","",C9+B9) -> 46229
A11: Secado | B11: 7 | C11: =IF(C10="","",C10+B10) -> 46230
A12: Procesado | B12: 3 | C12: =IF(C11="","",C11+B11) -> 46237
A13: Disponible | C13: =IF(C12="","",C12+B12) -> 46240
A15: VARIEDADES | B15: Cant.
A16: Brrberry | B16: 16
A17: Cherry Zoda | B17: 12
A18: Spritz | B18: 22
A19: TOTAL | B19: =SUM(B16:B18) -> 50
A21: Observaciones:
A25: CICLO 2
A26: Etapa | B26: Días | C26: Fecha Inicio
A27: Esquejes | B27: 21
A28: Trasplante a Vaso | B28: 14
A29: Trasplante Maceta | B29: 14
A30: Ingreso a Sala | B30: 16 | C30: =C12+1 -> 46238
A31: Floración | B31: 63 | C31: =IF(C30="","",C30+B30) -> 46254
A32: Corte | B32: 3 | C32: =IF(C31="","",C31+B31) -> 46317
A33: Secado | B33: 7 | C33: =IF(C32="","",C32+B32) -> 46320
A34: Procesado | B34: 3 | C34: =IF(C33="","",C33+B33) -> 46327
A35: Disponible | C35: =IF(C34="","",C34+B34) -> 46330
A37: VARIEDADES | B37: Cant.
A40: TOTAL | B40: =SUM(B38:B39) -> 0
A42: Observaciones:
A46: CICLO 3
A47: Etapa | B47: Días | C47: Fecha Inicio
A48: Esquejes | B48: 21
A49: Trasplante a Vaso | B49: 14
A50: Trasplante Maceta | B50: 14
A51: Ingreso a Sala | B51: 16 | C51: =C34+1 -> 46328
A52: Floración | B52: 63 | C52: =IF(C51="","",C51+B51) -> 46344
...

Sheet SALA 5
A1: 🌿 SALA 5 | H1: HISTORIAL pH / EC / TEMP / HUM
H2: Fecha | I2: pH | J2: EC (ppm) | K2: Temp °C | L2: Hum % | M2: PPFD (µmol/m²/s) | N2: Notas
A3: CICLO 1 | H3: 46184 | I3: 6.1 | J3: 2150
A4: Etapa | B4: Días | C4: Fecha Inicio
A5: Esquejes | B5: 21 | C5: 46113
A6: Trasplante a Vaso | B6: 14 | C6: =IF(C5="","",C5+B5) -> 46134
A7: Trasplante Maceta | B7: 14 | C7: =IF(C6="","",C6+B6) -> 46148
A8: Ingreso a Sala | B8: 16 | C8: =IF(C7="","",C7+B7) -> 46162
A9: Floración | B9: 63 | C9: =IF(C8="","",C8+B8) -> 46178
A10: Corte | B10: 1 | C10: =IF(C9="","",C9+B9) -> 46241
A11: Secado | B11: 7 | C11: =IF(C10="","",C10+B10) -> 46242
A12: Procesado | B12: 3 | C12: =IF(C11="","",C11+B11) -> 46249
A13: Disponible | C13: =IF(C12="","",C12+B12) -> 46252
A15: VARIEDADES | B15: Cant.
A16: Papaya Feno Hunting | B16: 33
A17: TOTAL | B17: =SUM(B16:B16) -> 33
A19: Observaciones:
A23: CICLO 2
A24: Etapa | B24: Días | C24: Fecha Inicio
A25: Esquejes | B25: 21
A26: Trasplante a Vaso | B26: 14
A27: Trasplante Maceta | B27: 14
A28: Ingreso a Sala | B28: 16 | C28: =C12+1 -> 46250
A29: Floración | B29: 63 | C29: =IF(C28="","",C28+B28) -> 46266
A30: Corte | B30: 1 | C30: =IF(C29="","",C29+B29) -> 46329
A31: Secado | B31: 7 | C31: =IF(C30="","",C30+B30) -> 46330
A32: Procesado | B32: 3 | C32: =IF(C31="","",C31+B31) -> 46337
A33: Disponible | C33: =IF(C32="","",C32+B32) -> 46340
A35: VARIEDADES | B35: Cant.
A37: TOTAL | B37: =SUM(B36:B36) -> 0
A39: Observaciones:
A43: CICLO 3
A44: Etapa | B44: Días | C44: Fecha Inicio
A45: Esquejes | B45: 21
A46: Trasplante a Vaso | B46: 14
A47: Trasplante Maceta | B47: 14
A48: Ingreso a Sala | B48: 16 | C48: =C32+1 -> 46338
A49: Floración | B49: 63 | C49: =IF(C48="","",C48+B48) -> 46354
A50: Corte | B50: 1 | C50: =IF(C49="","",C49+B49) -> 46417
A51: Secado | B51: 7 | C51: =IF(C50="","",C50+B50) -> 46418
...

Sheet SALA 6
A1: 🌿 SALA 6 | H1: HISTORIAL pH / EC / TEMP / HUM
H2: Fecha | I2: pH | J2: EC (ppm) | K2: Temp °C | L2: Hum % | M2: PPFD (µmol/m²/s) | N2: Notas
A3: CICLO 1 | H3: 46184 | I3: 5.95 | J3: 900
A4: Etapa | B4: Días | C4: Fecha Inicio
A5: Esquejes | B5: 21 | C5: 46058
A6: Trasplante a Vaso | B6: 14 | C6: =IF(C5="","",C5+B5) -> 46079
A7: Trasplante Maceta | B7: 14 | C7: =IF(C6="","",C6+B6) -> 46093
A8: Ingreso a Sala | B8: 16 | C8: =IF(C7="","",C7+B7) -> 46107
A9: Floración | B9: 63 | C9: =IF(C8="","",C8+B8) -> 46123
A10: Corte | B10: 1 | C10: =IF(C9="","",C9+B9) -> 46186
A11: Secado | B11: 7 | C11: =IF(C10="","",C10+B10) -> 46187
A12: Procesado | B12: 3 | C12: =IF(C11="","",C11+B11) -> 46194
A13: Disponible | C13: =IF(C12="","",C12+B12) -> 46197
A15: VARIEDADES | B15: Cant.
A16: Papaya Feno Hunting | B16: 22
A17: Cherry Zoda | B17: 19
A18: Brrberry | B18: 3
A19: Sour nana | B19: 1
A20: Spritz | B20: 3
A21: TOTAL | B21: =SUM(B16:B20) -> 48
A23: Observaciones:
A27: CICLO 2
A28: Etapa | B28: Días | C28: Fecha Inicio
A29: Esquejes | B29: 21
A30: Trasplante a Vaso | B30: 14
A31: Trasplante Maceta | B31: 14
A32: Ingreso a Sala | B32: 16 | C32: =C12+1 -> 46195
A33: Floración | B33: 63 | C33: =IF(C32="","",C32+B32) -> 46211
A34: Corte | B34: 1 | C34: =IF(C33="","",C33+B33) -> 46274
A35: Secado | B35: 7 | C35: =IF(C34="","",C34+B34) -> 46275
A36: Procesado | B36: 3 | C36: =IF(C35="","",C35+B35) -> 46282
A37: Disponible | C37: =IF(C36="","",C36+B36) -> 46285
A39: VARIEDADES | B39: Cant.
A42: TOTAL | B42: =SUM(B40:B41) -> 0
A44: Observaciones:
A48: CICLO 3
A49: Etapa | B49: Días | C49: Fecha Inicio
A50: Esquejes | B50: 21
A51: Trasplante a Vaso | B51: 14
A52: Trasplante Maceta | B52: 14
...

Sheet CARPA 1
A1: 🌿 CARPA 1 | H1: HISTORIAL pH / EC / TEMP / HUM
H2: Fecha | I2: pH | J2: EC (ppm) | K2: Temp °C | L2: Hum % | M2: PPFD (µmol/m²/s) | N2: Notas
A3: CICLO 1
A4: Etapa | B4: Días | C4: Fecha Inicio
A5: Ingreso a Carpa | B5: 20 | C5: 46178
A6: Floración | B6: 63 | C6: =IF(C5="","",C5+B5) -> 46198
A7: Corte | B7: 1 | C7: =IF(C6="","",C6+B6) -> 46261
A8: Secado | B8: 7 | C8: =IF(C7="","",C7+B7) -> 46262
A9: Procesado | B9: 3 | C9: =IF(C8="","",C8+B8) -> 46269
A10: Disponible | C10: =IF(C9="","",C9+B9) -> 46272
A12: VARIEDADES | B12: Cant.
A13: Cherry Zoda | B13: 3
A14: Hot tub time | B14: 2
A16: Papaya Feno Hunting | B16: 5
A17: TOTAL | B17: =SUM(B13:B16) -> 10
A19: Observaciones:
A23: CICLO 2
A24: Etapa | B24: Días | C24: Fecha Inicio
A25: Ingreso a Carpa | B25: 20 | C25: =C9+1 -> 46270
A26: Floración | B26: 63 | C26: =IF(C25="","",C25+B25) -> 46290
A27: Corte | B27: 1 | C27: =IF(C26="","",C26+B26) -> 46353
A28: Secado | B28: 7 | C28: =IF(C27="","",C27+B27) -> 46354
A29: Procesado | B29: 3 | C29: =IF(C28="","",C28+B28) -> 46361
A30: Disponible | C30: =IF(C29="","",C29+B29) -> 46364
A32: VARIEDADES | B32: Cant.
A35: TOTAL | B35: =SUM(B33:B34) -> 0
A37: Observaciones:
A41: CICLO 3
A42: Etapa | B42: Días | C42: Fecha Inicio
A43: Ingreso a Carpa | B43: 20 | C43: =C29+1 -> 46362
A44: Floración | B44: 63 | C44: =IF(C43="","",C43+B43) -> 46382
A45: Corte | B45: 1 | C45: =IF(C44="","",C44+B44) -> 46445
A46: Secado | B46: 7 | C46: =IF(C45="","",C45+B45) -> 46446
A47: Procesado | B47: 3 | C47: =IF(C46="","",C46+B46) -> 46453
A48: Disponible | C48: =IF(C47="","",C47+B47) -> 46456
A50: VARIEDADES | B50: Cant.
A53: TOTAL | B53: =SUM(B51:B52) -> 0
A55: Observaciones:
A59: CICLO 4
A60: Etapa | B60: Días | C60: Fecha Inicio
...

Sheet CARPA 2
A1: 🌿 CARPA 2 | H1: HISTORIAL pH / EC / TEMP / HUM
H2: Fecha | I2: pH | J2: EC (ppm) | K2: Temp °C | L2: Hum % | M2: PPFD (µmol/m²/s) | N2: Notas
A3: CICLO 1
A4: Etapa | B4: Días | C4: Fecha Inicio
A5: Ingreso a Carpa | B5: 20 | C5: 46159
A6: Floración | B6: 63 | C6: =IF(C5="","",C5+B5) -> 46179
A7: Corte | B7: 1 | C7: =IF(C6="","",C6+B6) -> 46242
A8: Secado | B8: 7 | C8: =IF(C7="","",C7+B7) -> 46243
A9: Procesado | B9: 3 | C9: =IF(C8="","",C8+B8) -> 46250
A10: Disponible | C10: =IF(C9="","",C9+B9) -> 46253
A12: VARIEDADES | B12: Cant.
A13: HTT Feno Hunt Mix | B13: 25
A14: TOTAL | B14: =SUM(B13:B13) -> 25
A16: Observaciones:
A20: CICLO 2
A21: Etapa | B21: Días | C21: Fecha Inicio
A22: Ingreso a Carpa | B22: 20 | C22: =C9+1 -> 46251
A23: Floración | B23: 63 | C23: =IF(C22="","",C22+B22) -> 46271
A24: Corte | B24: 1 | C24: =IF(C23="","",C23+B23) -> 46334
A25: Secado | B25: 7 | C25: =IF(C24="","",C24+B24) -> 46335
A26: Procesado | B26: 3 | C26: =IF(C25="","",C25+B25) -> 46342
A27: Disponible | C27: =IF(C26="","",C26+B26) -> 46345
A29: VARIEDADES | B29: Cant.
A31: TOTAL | B31: =SUM(B30:B30) -> 0
A33: Observaciones:
A37: CICLO 3
A38: Etapa | B38: Días | C38: Fecha Inicio
A39: Ingreso a Carpa | B39: 20 | C39: =C26+1 -> 46343
A40: Floración | B40: 63 | C40: =IF(C39="","",C39+B39) -> 46363
A41: Corte | B41: 1 | C41: =IF(C40="","",C40+B40) -> 46426
A42: Secado | B42: 7 | C42: =IF(C41="","",C41+B41) -> 46427
A43: Procesado | B43: 3 | C43: =IF(C42="","",C42+B42) -> 46434
A44: Disponible | C44: =IF(C43="","",C43+B43) -> 46437
A46: VARIEDADES | B46: Cant.
A48: TOTAL | B48: =SUM(B47:B47) -> 0
A50: Observaciones:
A54: CICLO 4
A55: Etapa | B55: Días | C55: Fecha Inicio
A56: Ingreso a Carpa | B56: 20 | C56: =C43+1 -> 46435
A57: Floración | B57: 63 | C57: =IF(C56="","",C56+B56) -> 46455
...

Sheet CARPA 3
A1: 🌿 CARPA 3 | H1: HISTORIAL pH / EC / TEMP / HUM
H2: Fecha | I2: pH | J2: EC (ppm) | K2: Temp °C | L2: Hum % | M2: PPFD (µmol/m²/s) | N2: Notas
A3: CICLO 1
A4: Etapa | B4: Días | C4: Fecha Inicio
A5: Ingreso a Carpa | B5: 20 | C5: 46120
A6: Floración | B6: 63 | C6: =IF(C5="","",C5+B5) -> 46140
A7: Corte | B7: 1 | C7: =IF(C6="","",C6+B6) -> 46203
A8: Secado | B8: 7 | C8: =IF(C7="","",C7+B7) -> 46204
A9: Procesado | B9: 3 | C9: =IF(C8="","",C8+B8) -> 46211
A10: Disponible | C10: =IF(C9="","",C9+B9) -> 46214
A12: VARIEDADES | B12: Cant.
A13: Guava | B13: 37
A14: TOTAL | B14: =SUM(B13:B13) -> 37
A16: Observaciones:
A20: CICLO 2
A21: Etapa | B21: Días | C21: Fecha Inicio
A22: Ingreso a Carpa | B22: 20 | C22: =C9+1 -> 46212
A23: Floración | B23: 63 | C23: =IF(C22="","",C22+B22) -> 46232
A24: Corte | B24: 1 | C24: =IF(C23="","",C23+B23) -> 46295
A25: Secado | B25: 7 | C25: =IF(C24="","",C24+B24) -> 46296
A26: Procesado | B26: 3 | C26: =IF(C25="","",C25+B25) -> 46303
A27: Disponible | C27: =IF(C26="","",C26+B26) -> 46306
A29: VARIEDADES | B29: Cant.
A31: TOTAL | B31: =SUM(B30:B30) -> 0
A33: Observaciones:
A37: CICLO 3
A38: Etapa | B38: Días | C38: Fecha Inicio
A39: Ingreso a Carpa | B39: 20 | C39: =C26+1 -> 46304
A40: Floración | B40: 63 | C40: =IF(C39="","",C39+B39) -> 46324
A41: Corte | B41: 1 | C41: =IF(C40="","",C40+B40) -> 46387
A42: Secado | B42: 7 | C42: =IF(C41="","",C41+B41) -> 46388
A43: Procesado | B43: 3 | C43: =IF(C42="","",C42+B42) -> 46395
A44: Disponible | C44: =IF(C43="","",C43+B43) -> 46398
A46: VARIEDADES | B46: Cant.
A48: TOTAL | B48: =SUM(B47:B47) -> 0
A50: Observaciones:
A54: CICLO 4
A55: Etapa | B55: Días | C55: Fecha Inicio
A56: Ingreso a Carpa | B56: 20 | C56: =C43+1 -> 46396
A57: Floración | B57: 63 | C57: =IF(C56="","",C56+B56) -> 46416
...

Sheet CARPA 4
A1: 🌿 CARPA 4 | H1: HISTORIAL pH / EC / TEMP / HUM
H2: Fecha | I2: pH | J2: EC (ppm) | K2: Temp °C | L2: Hum % | M2: PPFD (µmol/m²/s) | N2: Notas
A3: CICLO 1
A4: Etapa | B4: Días | C4: Fecha Inicio
A5: Ingreso a Carpa | B5: 20 | C5: 46182
A6: Floración | B6: 63 | C6: =IF(C5="","",C5+B5) -> 46202
A7: Corte | B7: 1 | C7: =IF(C6="","",C6+B6) -> 46265
A8: Secado | B8: 7 | C8: =IF(C7="","",C7+B7) -> 46266
A9: Procesado | B9: 3 | C9: =IF(C8="","",C8+B8) -> 46273
A10: Disponible | C10: =IF(C9="","",C9+B9) -> 46276
A12: VARIEDADES | B12: Cant.
A13: Coco | B13: 14
A14: TOTAL | B14: =SUM(B13:B13) -> 14
A16: Observaciones:
A20: CICLO 2
A21: Etapa | B21: Días | C21: Fecha Inicio
A22: Ingreso a Carpa | B22: 20 | C22: =C9+1 -> 46274
A23: Floración | B23: 63 | C23: =IF(C22="","",C22+B22) -> 46294
A24: Corte | B24: 1 | C24: =IF(C23="","",C23+B23) -> 46357
A25: Secado | B25: 7 | C25: =IF(C24="","",C24+B24) -> 46358
A26: Procesado | B26: 3 | C26: =IF(C25="","",C25+B25) -> 46365
A27: Disponible | C27: =IF(C26="","",C26+B26) -> 46368
A29: VARIEDADES | B29: Cant.
A31: TOTAL | B31: =SUM(B30:B30) -> 0
A33: Observaciones:
A37: CICLO 3
A38: Etapa | B38: Días | C38: Fecha Inicio
A39: Ingreso a Carpa | B39: 20 | C39: =C26+1 -> 46366
A40: Floración | B40: 63 | C40: =IF(C39="","",C39+B39) -> 46386
A41: Corte | B41: 1 | C41: =IF(C40="","",C40+B40) -> 46449
A42: Secado | B42: 7 | C42: =IF(C41="","",C41+B41) -> 46450
A43: Procesado | B43: 3 | C43: =IF(C42="","",C42+B42) -> 46457
A44: Disponible | C44: =IF(C43="","",C43+B43) -> 46460
A46: VARIEDADES | B46: Cant.
A48: TOTAL | B48: =SUM(B47:B47) -> 0
A50: Observaciones:
A54: CICLO 4
A55: Etapa | B55: Días | C55: Fecha Inicio
A56: Ingreso a Carpa | B56: 20 | C56: =C43+1 -> 46458
A57: Floración | B57: 63 | C57: =IF(C56="","",C56+B56) -> 46478
...

Sheet PESOS
A1: ⚖️ REGISTRO DE PESOS — Cosechas por Sala/Carpa (peso final seco)
A2: ℹ️ La Fecha de Corte se trae automáticamente de cada hoja de Sala/Carpa. Ingresa el Peso Final Seco TOTAL del ciclo en la primera fila de cada ciclo (celda amarilla); el reparto por variedad y sus % se calculan solos según la cantidad de plantas registrada en esa hoja.
A4: SALA 1
A5: Ciclo | B5: Fecha Corte | C5: Variedad | D5: % Plantas | E5: Peso Final Seco (g) | F5: Peso Final Seco (kg) | G5: Notas
A6: CICLO 1 | B6: =IF('SALA 1'!C9="","",'SALA 1'!C9) -> 46250 | C6: Coco | D6: =IF('SALA 1'!B18=0,"",'SALA 1'!B16/'SALA 1'!B18) -> 0.38888889 | F6: =IF(E6="","",E6/1000)
B7: =IF('SALA 1'!C9="","",'SALA 1'!C9) -> 46250 | C7: MR | D7: =IF('SALA 1'!B18=0,"",'SALA 1'!B17/'SALA 1'!B18) -> 0.61111111 | E7: =IF($E$6="","",$E$6*D7) | F7: =IF(E7="","",E7/1000)
C8: TOTAL CICLO | E8: =IF(E6="","",E6) | F8: =IF(E6="","",E6/1000)
A9: CICLO 3 | B9: =IF('SALA 1'!C52="","",'SALA 1'!C52) -> 46428 | C9: (sin variedad) | F9: =IF(E9="","",E9/1000)
A11: SALA 2
A12: Ciclo | B12: Fecha Corte | C12: Variedad | D12: % Plantas | E12: Peso Final Seco (g) | F12: Peso Final Seco (kg) | G12: Notas
A13: CICLO 1 | B13: =IF('SALA 2'!C10="","",'SALA 2'!C10) -> 46209 | C13: Guava | D13: =IF('SALA 2'!B18=0,"",'SALA 2'!B16/'SALA 2'!B18) -> 0.75 | F13: =IF(E13="","",E13/1000)
B14: =IF('SALA 2'!C10="","",'SALA 2'!C10) -> 46209 | C14: Mix | D14: =IF('SALA 2'!B18=0,"",'SALA 2'!B17/'SALA 2'!B18) -> 0.25 | E14: =IF($E$13="","",$E$13*D14) | F14: =IF(E14="","",E14/1000)
C15: TOTAL CICLO | E15: =IF(E13="","",E13) | F15: =IF(E13="","",E13/1000)
A16: CICLO 2 | B16: =IF('SALA 2'!C31="","",'SALA 2'!C31) -> 46298 | C16: (sin variedad) | F16: =IF(E16="","",E16/1000)
A17: CICLO 3 | B17: =IF('SALA 2'!C52="","",'SALA 2'!C52) -> 46386 | C17: (sin variedad) | F17: =IF(E17="","",E17/1000)
A19: SALA 3
A20: Ciclo | B20: Fecha Corte | C20: Variedad | D20: % Plantas | E20: Peso Final Seco (g) | F20: Peso Final Seco (kg) | G20: Notas
A21: CICLO 1 | B21: =IF('SALA 3'!C10="","",'SALA 3'!C10) -> 46223 | C21: Lemon Cherry | D21: =IF('SALA 3'!B20=0,"",'SALA 3'!B16/'SALA 3'!B20) -> 0.25 | F21: =IF(E21="","",E21/1000)
B22: =IF('SALA 3'!C10="","",'SALA 3'!C10) -> 46223 | C22: Frozen Biscotti #2 | D22: =IF('SALA 3'!B20=0,"",'SALA 3'!B17/'SALA 3'!B20) -> 0.36111111 | E22: =IF($E$21="","",$E$21*D22) | F22: =IF(E22="","",E22/1000)
B23: =IF('SALA 3'!C10="","",'SALA 3'!C10) -> 46223 | C23: HTT #4 | D23: =IF('SALA 3'!B20=0,"",'SALA 3'!B18/'SALA 3'!B20) -> 0.26388889 | E23: =IF($E$21="","",$E$21*D23) | F23: =IF(E23="","",E23/1000)
B24: =IF('SALA 3'!C10="","",'SALA 3'!C10) -> 46223 | C24: Blue Zushi | D24: =IF('SALA 3'!B20=0,"",'SALA 3'!B19/'SALA 3'!B20) -> 0.125 | E24: =IF($E$21="","",$E$21*D24) | F24: =IF(E24="","",E24/1000)
C25: TOTAL CICLO | E25: =IF(E21="","",E21) | F25: =IF(E21="","",E21/1000)
A26: CICLO 2 | B26: =IF('SALA 3'!C33="","",'SALA 3'!C33) -> 46311 | C26: (sin variedad) | F26: =IF(E26="","",E26/1000)
A27: CICLO 3 | B27: =IF('SALA 3'!C54="","",'SALA 3'!C54) -> 46401 | C27: (sin variedad) | F27: =IF(E27="","",E27/1000)
A29: SALA 4
A30: Ciclo | B30: Fecha Corte | C30: Variedad | D30: % Plantas | E30: Peso Final Seco (g) | F30: Peso Final Seco (kg) | G30: Notas
A31: CICLO 1 | B31: =IF('SALA 4'!C10="","",'SALA 4'!C10) -> 46229 | C31: Brrberry | D31: =IF('SALA 4'!B19=0,"",'SALA 4'!B16/'SALA 4'!B19) -> 0.32 | F31: =IF(E31="","",E31/1000)
B32: =IF('SALA 4'!C10="","",'SALA 4'!C10) -> 46229 | C32: Cherry Zoda | D32: =IF('SALA 4'!B19=0,"",'SALA 4'!B17/'SALA 4'!B19) -> 0.24 | E32: =IF($E$31="","",$E$31*D32) | F32: =IF(E32="","",E32/1000)
B33: =IF('SALA 4'!C10="","",'SALA 4'!C10) -> 46229 | C33: Spritz | D33: =IF('SALA 4'!B19=0,"",'SALA 4'!B18/'SALA 4'!B19) -> 0.44 | E33: =IF($E$31="","",$E$31*D33) | F33: =IF(E33="","",E33/1000)
C34: TOTAL CICLO | E34: =IF(E31="","",E31) | F34: =IF(E31="","",E31/1000)
A35: CICLO 2 | B35: =IF('SALA 4'!C32="","",'SALA 4'!C32) -> 46317 | C35: (sin variedad) | F35: =IF(E35="","",E35/1000)
A36: CICLO 3 | B36: =IF('SALA 4'!C53="","",'SALA 4'!C53) -> 46407 | C36: (sin variedad) | F36: =IF(E36="","",E36/1000)
A38: SALA 5
A39: Ciclo | B39: Fecha Corte | C39: Variedad | D39: % Plantas | E39: Peso Final Seco (g) | F39: Peso Final Seco (kg) | G39: Notas
A40: CICLO 1 | B40: =IF('SALA 5'!C10="","",'SALA 5'!C10) -> 46241 | C40: Papaya Feno Hunting | D40: =IF('SALA 5'!B17=0,"",'SALA 5'!B16/'SALA 5'!B17) -> 1 | F40: =IF(E40="","",E40/1000)
A41: CICLO 2 | B41: =IF('SALA 5'!C30="","",'SALA 5'!C30) -> 46329 | C41: (sin variedad) | F41: =IF(E41="","",E41/1000)
A42: CICLO 3 | B42: =IF('SALA 5'!C50="","",'SALA 5'!C50) -> 46417 | C42: (sin variedad) | F42: =IF(E42="","",E42/1000)
A44: SALA 6
A45: Ciclo | B45: Fecha Corte | C45: Variedad | D45: % Plantas | E45: Peso Final Seco (g) | F45: Peso Final Seco (kg) | G45: Notas
A46: CICLO 1 | B46: =IF('SALA 6'!C10="","",'SALA 6'!C10) -> 46186 | C46: Papaya Feno Hunting | D46: =IF('SALA 6'!B21=0,"",'SALA 6'!B16/'SALA 6'!B21) -> 0.45833333 | F46: =IF(E46="","",E46/1000)
...

Sheet LEYENDA
A1: LEYENDA Y GUÍA DE USO
A3: Celda amarilla | C3: Campo de entrada manual — escribe aquí tus datos
A4: Texto azul (días) | C4: Duración de etapa — puedes modificar según tu ciclo
A5: Fondo verde claro | C5: Encabezado de sección
A6: Texto verde | C6: Nombre de sala/carpa en resumen
A8: FLUJO ESTÁNDAR — SALAS
A9: Esquejes (21d) | B9: → Trasplante Vaso (14d) | C9: → Trasplante Maceta (14d) | D9: → Ingreso Sala (16d) | E9: → Floración (63d) | F9: → Corte (1d) | G9: → Secado (7d) | H9: → Procesado (3d) | I9: → Disponible
A11: FLUJO ESTÁNDAR — CARPAS
A12: Ingreso a Carpa (20d) | B12: → Floración (63d) | C12: → Corte (1d) | D12: → Secado (7d) | E12: → Procesado (3d) | F12: → Disponible
